<?xml version="1.0"?>
<robot name="vmecanumrover" xmlns:xacro="http://ros.org/wiki/xacro">

  <xacro:macro name="sus" params="prefix">

    <joint name="${prefix}_sus_joint" type="prismatic">
      <parent link="${prefix}_base_link"/>
      <child  link="${prefix}_sus_link"/>
      <limit lower="-0.02" upper="0.02" effort="100" velocity="1.0" />
      <axis xyz="0 0 1"/>
      <origin xyz="0 0 0" rpy="0 0 0"/>
      <dynamics damping="0.01"/>
    </joint>

    <transmission name="${prefix}_sus_trans">
      <type>transmission_interface/SimpleTransmission</type>
      <joint name="${prefix}_sus_joint">
          <hardwareInterface>hardware_interface/EffortJointInterface</hardwareInterface>
      </joint>
      <actuator name="${prefix}_sus_motor">
        <hardwareInterface>hardware_interface/EffortJointInterface</hardwareInterface>
        <mechanismReduction>1</mechanismReduction>
      </actuator>
    </transmission>

    <gazebo reference="${prefix}_sus_joint">
      <kp>50000</kp>
      <kd>500</kd>
    </gazebo>

    <link name="${prefix}_sus_link">
      <inertial>
        <mass value="0.010"/>
        <inertia ixx="0.00001" ixy="0.0" ixz="0.0" iyy="0.00001" iyz="0.0" izz="0.00001"/>
      </inertial>
    </link>

  </xacro:macro>

</robot>